Workbook

Sheet stock_valuation_layer
A1: Reference | B1: Consumption Date | C1: Product | D1: Product Category | E1: Quantity | F1: Unit of Measure | G1: Unit Value | H1: Total Value
A2: MK/MO/07016 | B2: =_xlfn.XLOOKUP(A2,mrp_production!A:A,mrp_production!C:C) -> 45942 | C2: [9001268] Indian Basmati Rice - Ashoka - 20Kg | D2: Raw Materials / Rice | E2: -14 | F2: Bag of 20kg | G2: 9.8 | H2: -137.2
A3: MK/MO/07016 | B3: =_xlfn.XLOOKUP(A3,mrp_production!A:A,mrp_production!C:C) -> 45942 | C3: [9001234] Vegetable Oil - 17L | D3: Raw Materials / Oil & Ghee | E3: -4 | F3: Tin of 17L - | G3: 8.2 | H3: -32.8
A4: MK/MO/07016 | B4: =_xlfn.XLOOKUP(A4,mrp_production!A:A,mrp_production!C:C) -> 45942 | C4: [9001122] Pure Ghee - 1600g | D4: Raw Materials / Diary & Juice | E4: -0.5 | F4: ctn of 6 Tin of 1600g | G4: 36.5 | H4: -18.25
A5: MK/MO/07016 | B5: =_xlfn.XLOOKUP(A5,mrp_production!A:A,mrp_production!C:C) -> 45942 | C5: [9001251] Chana Dal - 15Kg | D5: Raw Materials / Pulses | E5: -0.133 | F5: Bag of 15kg | G5: 5.398 | H5: -0.718
A6: MK/MO/07016 | B6: =_xlfn.XLOOKUP(A6,mrp_production!A:A,mrp_production!C:C) -> 45942 | C6: [9001216] Sugar - 50kg | D6: Raw Materials / Grocery | E6: -1 | F6: Bag of 50kg | G6: 11.5 | H6: -11.5
A7: MK/MO/07016 | B7: =_xlfn.XLOOKUP(A7,mrp_production!A:A,mrp_production!C:C) -> 45942 | C7: [9001336] Custard Powder - 400g | D7: Raw Materials / Grocery | E7: -1 | F7: ctn of 12 tin of 400g | G7: 12.4 | H7: -12.4
A8: MK/MO/07016 | B8: =_xlfn.XLOOKUP(A8,mrp_production!A:A,mrp_production!C:C) -> 45942 | C8: [9001172] Egg Jordan - 360 Pcs | D8: Raw Materials / Fresh Meat & Poultry | E8: -0.167 | F8: ctn of 12 tray of 30pcs | G8: 19 | H8: -3.173
A9: MK/MO/07016 | B9: =_xlfn.XLOOKUP(A9,mrp_production!A:A,mrp_production!C:C) -> 45942 | C9: [9001176] Food Colour - Yellow 100g | D9: Raw Materials / Grocery | E9: -0.017 | F9: ctn of 120Pkt of 100g | G9: 33.176 | H9: -0.564
A10: MK/MO/07016 | B10: =_xlfn.XLOOKUP(A10,mrp_production!A:A,mrp_production!C:C) -> 45942 | C10: [9001178] Golden Raisin - 10Kg | D10: Raw Materials / Grocery | E10: -0.15 | F10: Bag of 10kg | G10: 10.6 | H10: -1.59
A11: MK/MO/07016 | B11: =_xlfn.XLOOKUP(A11,mrp_production!A:A,mrp_production!C:C) -> 45942 | C11: [9001190] Kewra Water - 200ml | D11: Raw Materials / Grocery | E11: -2 | F11: Btl 200ml | G11: 0.65 | H11: -1.3
A12: MK/MO/07016 | B12: =_xlfn.XLOOKUP(A12,mrp_production!A:A,mrp_production!C:C) -> 45942 | C12: [9001192] Lemon Juice - 946ml | D12: Raw Materials / Grocery | E12: -0.417 | F12: ctn of 12 bottle of 946ml | G12: 5.201 | H12: -2.169
A13: MK/MO/07016 | B13: =_xlfn.XLOOKUP(A13,mrp_production!A:A,mrp_production!C:C) -> 45942 | C13: [9001194] Maida - 50kg | D13: Raw Materials / Grocery | E13: -0.1 | F13: Bag of 50kg | G13: 3.7 | H13: -0.37
... A140: MK/MO/07018 | B140: =_xlfn.XLOOKUP(A140,mrp_production!A:A,mrp_production!C:C) -> 45942 | C140: [9001004] Garbage Bag - 70gal - 30Pcs | D140: Cleaning & Hygienic Materials | E140: 0 | F140: ctn of 12 pkt | G140: 0 | H140: 0.001

Sheet mrp_production
A1: Reference | B1: Product | C1: Consumption Date | D1: Components/Product | E1: Components/Quantity
A2: MK/MO/07016 | B2: [MK5001025] Riffa Consumption | C2: 45942 | D2: [9001268] Indian Basmati Rice - Ashoka - 20Kg | E2: 14
A3: =A2 -> MK/MO/07016 | B3: =B2 -> [MK5001025] Riffa Consumption | C3: =C2 -> 45942 | D3: [9001234] Vegetable Oil - 17L | E3: 4
A4: =A3 -> MK/MO/07016 | B4: =B3 -> [MK5001025] Riffa Consumption | C4: =C3 -> 45942 | D4: [9001122] Pure Ghee - 1600g | E4: 3
A5: =A4 -> MK/MO/07016 | B5: =B4 -> [MK5001025] Riffa Consumption | C5: =C4 -> 45942 | D5: [9001251] Chana Dal - 15Kg | E5: 2
A6: =A5 -> MK/MO/07016 | B6: =B5 -> [MK5001025] Riffa Consumption | C6: =C5 -> 45942 | D6: [9001216] Sugar - 50kg | E6: 1
A7: =A6 -> MK/MO/07016 | B7: =B6 -> [MK5001025] Riffa Consumption | C7: =C6 -> 45942 | D7: [9001336] Custard Powder - 400g | E7: 12
A8: =A7 -> MK/MO/07016 | B8: =B7 -> [MK5001025] Riffa Consumption | C8: =C7 -> 45942 | D8: [9001172] Egg Jordan - 360 Pcs | E8: 2
A9: =A8 -> MK/MO/07016 | B9: =B8 -> [MK5001025] Riffa Consumption | C9: =C8 -> 45942 | D9: [9001176] Food Colour - Yellow 100g | E9: 2
A10: =A9 -> MK/MO/07016 | B10: =B9 -> [MK5001025] Riffa Consumption | C10: =C9 -> 45942 | D10: [9001178] Golden Raisin - 10Kg | E10: 1.5
A11: =A10 -> MK/MO/07016 | B11: =B10 -> [MK5001025] Riffa Consumption | C11: =C10 -> 45942 | D11: [9001190] Kewra Water - 200ml | E11: 2
A12: =A11 -> MK/MO/07016 | B12: =B11 -> [MK5001025] Riffa Consumption | C12: =C11 -> 45942 | D12: [9001192] Lemon Juice - 946ml | E12: 5
A13: =A12 -> MK/MO/07016 | B13: =B12 -> [MK5001025] Riffa Consumption | C13: =C12 -> 45942 | D13: [9001194] Maida - 50kg | E13: 5
A14: =A13 -> MK/MO/07016 | B14: =B13 -> [MK5001025] Riffa Consumption | C14: =C13 -> 45942 | D14: [9001628] Milk Powder - Born Lite - 25Kg | E14: 1
... A47: =A46 -> MK/MO/07016 | B47: =B46 -> [MK5001025] Riffa Consumption | C47: =C46 -> 45942 | D47: [9001243] Chicken Cheese Stick - 5Kg | E47: 3
A48: MK/MO/07017 | B48: [MK5001025] Riffa Consumption | C48: 45942 | D48: [9001463] Basmati Rice - Pappaya - 20Kg | E48: 40
A49: =A48 -> MK/MO/07017 | B49: =B48 -> [MK5001025] Riffa Consumption | C49: =C48 -> 45942 | D49: [9001270] Kuruva Rice - 30Kg | E49: 28
A50: =A49 -> MK/MO/07017 | B50: =B49 -> [MK5001025] Riffa Consumption | C50: =C49 -> 45942 | D50: [9001234] Vegetable Oil - 17L | E50: 2
A51: =A50 -> MK/MO/07017 | B51: =B50 -> [MK5001025] Riffa Consumption | C51: =C50 -> 45942 | D51: [9001107] Ghee - 1 Ltr | E51: 1
A52: =A51 -> MK/MO/07017 | B52: =B51 -> [MK5001025] Riffa Consumption | C52: =C51 -> 45942 | D52: [9001260] Masoor Dal - 15Kg | E52: 40
A53: =A52 -> MK/MO/07017 | B53: =B52 -> [MK5001025] Riffa Consumption | C53: =C52 -> 45942 | D53: [9001249] Black Eye Beans - 15Kg | E53: 5
A54: =A53 -> MK/MO/07017 | B54: =B53 -> [MK5001025] Riffa Consumption | C54: =C53 -> 45942 | D54: [9001331] Pappad - Madras - 100g | E54: 1
A55: =A54 -> MK/MO/07017 | B55: =B54 -> [MK5001025] Riffa Consumption | C55: =C54 -> 45942 | D55: [9001163] Cocunut Peera | E55: 3
A56: =A55 -> MK/MO/07017 | B56: =B55 -> [MK5001025] Riffa Consumption | C56: =C55 -> 45942 | D56: [9001192] Lemon Juice - 946ml | E56: 1
A57: =A56 -> MK/MO/07017 | B57: =B56 -> [MK5001025] Riffa Consumption | C57: =C56 -> 45942 | D57: [9001222] Tomato Paste - 4.5Kg | E57: 1
A58: =A57 -> MK/MO/07017 | B58: =B57 -> [MK5001025] Riffa Consumption | C58: =C57 -> 45942 | D58: [9001317] LG Powder 100g | E58: 1
A59: =A58 -> MK/MO/07017 | B59: =B58 -> [MK5001025] Riffa Consumption | C59: =C58 -> 45942 | D59: [9001651] Ajinomoto - 400g | E59: 1
A60: =A59 -> MK/MO/07017 | B60: =B59 -> [MK5001025] Riffa Consumption | C60: =C59 -> 45942 | D60: [9001303] Tamarind - 20Kg | E60: 1
... A72: =A71 -> MK/MO/07017 | B72: =B71 -> [MK5001025] Riffa Consumption | C72: =C71 -> 45942 | D72: [9001146] Frozen Cauliflower - 2.5Kg | E72: 1
A73: MK/MO/07018 | B73: [MK5001001] Maameer General Consumption | C73: 45942 | D73: [9001002] Dishwash - 30L | E73: 3
A74: =A73 -> MK/MO/07018 | B74: =B73 -> [MK5001001] Maameer General Consumption | C74: =C73 -> 45942 | D74: [9001351] Clorox 30L | E74: 2
A75: =A74 -> MK/MO/07018 | B75: =B74 -> [MK5001001] Maameer General Consumption | C75: =C74 -> 45942 | D75: [9001013] Vinyl Hand Gloves Blue - 100Pcs | E75: 2
A76: =A75 -> MK/MO/07018 | B76: =B75 -> [MK5001001] Maameer General Consumption | C76: =C75 -> 45942 | D76: [9001422] Maxi Roll - 750g | E76: 4
A77: =A76 -> MK/MO/07018 | B77: =B76 -> [MK5001001] Maameer General Consumption | C77: =C76 -> 45942 | D77: [9001004] Garbage Bag - 70gal - 30Pcs | E77: 1
A78: MK/MO/06984 | B78: [MK5001026] Jau Consumption | C78: 45942 | D78: [9001266] Basmati Rice - Al Khairth - 20Kg | E78: 8
A79: =A78 -> MK/MO/06984 | B79: =B78 -> [MK5001026] Jau Consumption | C79: =C78 -> 45942 | D79: [9001272] Sella Rice - Al Furat - 20Kg | E79: 30
A80: =A79 -> MK/MO/06984 | B80: =B79 -> [MK5001026] Jau Consumption | C80: =C79 -> 45942 | D80: [9001234] Vegetable Oil - 17L | E80: 12
A81: =A80 -> MK/MO/06984 | B81: =B80 -> [MK5001026] Jau Consumption | C81: =C80 -> 45942 | D81: [9001107] Ghee - 1 Ltr | E81: 3
A82: =A81 -> MK/MO/06984 | B82: =B81 -> [MK5001026] Jau Consumption | C82: =C81 -> 45942 | D82: [9001260] Masoor Dal - 15Kg | E82: 6
A83: =A82 -> MK/MO/06984 | B83: =B82 -> [MK5001026] Jau Consumption | C83: =C82 -> 45942 | D83: [9001155] Black Salt - Kg | E83: 3
...
